<?xml version="1.0" encoding="UTF-8"?>
<!-- Generated by org.testng.reporters.JUnitReportReporter -->
<testsuite hostname="poorani-PC" name="com.Selenium.TestNGPackage.TestNGPriority" tests="5" failures="2" timestamp="5 Apr 2019 02:23:59 GMT" time="0.029" errors="1">
  <testcase name="tc05" time="0.000" classname="com.Selenium.TestNGPackage.TestNGPriority">
    <error type="java.lang.Throwable" message="Method TestNGPriority.tc05()[pri:0, instance:com.Selenium.TestNGPackage.TestNGPriority@ee68d8] depends on not successfully finished methods">
      <![CDATA[java.lang.Throwable: Method TestNGPriority.tc05()[pri:0, instance:com.Selenium.TestNGPackage.TestNGPriority@ee68d8] depends on not successfully finished methods
	at org.testng.internal.Invoker.invokeTestMethods(Invoker.java:1033)
	at org.testng.internal.TestMethodWorker.invokeTestMethods(TestMethodWorker.java:125)
	at org.testng.internal.TestMethodWorker.run(TestMethodWorker.java:108)
	at org.testng.TestRunner.privateRun(TestRunner.java:774)
	at org.testng.TestRunner.run(TestRunner.java:624)
	at org.testng.SuiteRunner.runTest(SuiteRunner.java:359)
	at org.testng.SuiteRunner.runSequentially(SuiteRunner.java:354)
	at org.testng.SuiteRunner.privateRun(SuiteRunner.java:312)
	at org.testng.SuiteRunner.run(SuiteRunner.java:261)
	at org.testng.SuiteRunnerWorker.runSuite(SuiteRunnerWorker.java:52)
	at org.testng.SuiteRunnerWorker.run(SuiteRunnerWorker.java:86)
	at org.testng.TestNG.runSuitesSequentially(TestNG.java:1215)
	at org.testng.TestNG.runSuitesLocally(TestNG.java:1140)
	at org.testng.TestNG.run(TestNG.java:1048)
	at org.testng.remote.AbstractRemoteTestNG.run(AbstractRemoteTestNG.java:132)
	at org.testng.remote.RemoteTestNG.initAndRun(RemoteTestNG.java:230)
	at org.testng.remote.RemoteTestNG.main(RemoteTestNG.java:76)
]]>
    </error>
  </testcase> <!-- tc05 -->
  <testcase name="tc04" time="0.001" classname="com.Selenium.TestNGPackage.TestNGPriority">
    <failure type="java.lang.AssertionError" message="Hai">
      <![CDATA[java.lang.AssertionError: Hai
	at org.testng.Assert.fail(Assert.java:94)
	at com.Selenium.TestNGPackage.TestNGPriority.tc04(TestNGPriority.java:30)
	at sun.reflect.NativeMethodAccessorImpl.invoke0(Native Method)
	at sun.reflect.NativeMethodAccessorImpl.invoke(Unknown Source)
	at sun.reflect.DelegatingMethodAccessorImpl.invoke(Unknown Source)
	at java.lang.reflect.Method.invoke(Unknown Source)
	at org.testng.internal.MethodInvocationHelper.invokeMethod(MethodInvocationHelper.java:85)
	at org.testng.internal.Invoker.invokeMethod(Invoker.java:639)
	at org.testng.internal.Invoker.invokeTestMethod(Invoker.java:816)
	at org.testng.internal.Invoker.invokeTestMethods(Invoker.java:1124)
	at org.testng.internal.TestMethodWorker.invokeTestMethods(TestMethodWorker.java:125)
	at org.testng.internal.TestMethodWorker.run(TestMethodWorker.java:108)
	at org.testng.TestRunner.privateRun(TestRunner.java:774)
	at org.testng.TestRunner.run(TestRunner.java:624)
	at org.testng.SuiteRunner.runTest(SuiteRunner.java:359)
	at org.testng.SuiteRunner.runSequentially(SuiteRunner.java:354)
	at org.testng.SuiteRunner.privateRun(SuiteRunner.java:312)
	at org.testng.SuiteRunner.run(SuiteRunner.java:261)
	at org.testng.SuiteRunnerWorker.runSuite(SuiteRunnerWorker.java:52)
	at org.testng.SuiteRunnerWorker.run(SuiteRunnerWorker.java:86)
	at org.testng.TestNG.runSuitesSequentially(TestNG.java:1215)
	at org.testng.TestNG.runSuitesLocally(TestNG.java:1140)
	at org.testng.TestNG.run(TestNG.java:1048)
	at org.testng.remote.AbstractRemoteTestNG.run(AbstractRemoteTestNG.java:132)
	at org.testng.remote.RemoteTestNG.initAndRun(RemoteTestNG.java:230)
	at org.testng.remote.RemoteTestNG.main(RemoteTestNG.java:76)
]]>
    </failure>
  </testcase> <!-- tc04 -->
  <testcase name="tc02" time="0.004" classname="com.Selenium.TestNGPackage.TestNGPriority"/>
  <testcase name="tc01" time="0.001" classname="com.Selenium.TestNGPackage.TestNGPriority"/>
  <testcase name="tc03" time="0.023" classname="com.Selenium.TestNGPackage.TestNGPriority">
    <failure type="java.lang.AssertionError" message="Hai">
      <![CDATA[java.lang.AssertionError: Hai
	at org.testng.Assert.fail(Assert.java:94)
	at com.Selenium.TestNGPackage.TestNGPriority.tc03(TestNGPriority.java:22)
	at sun.reflect.NativeMethodAccessorImpl.invoke0(Native Method)
	at sun.reflect.NativeMethodAccessorImpl.invoke(Unknown Source)
	at sun.reflect.DelegatingMethodAccessorImpl.invoke(Unknown Source)
	at java.lang.reflect.Method.invoke(Unknown Source)
	at org.testng.internal.MethodInvocationHelper.invokeMethod(MethodInvocationHelper.java:85)
	at org.testng.internal.Invoker.invokeMethod(Invoker.java:639)
	at org.testng.internal.Invoker.invokeTestMethod(Invoker.java:816)
	at org.testng.internal.Invoker.invokeTestMethods(Invoker.java:1124)
	at org.testng.internal.TestMethodWorker.invokeTestMethods(TestMethodWorker.java:125)
	at org.testng.internal.TestMethodWorker.run(TestMethodWorker.java:108)
	at org.testng.TestRunner.privateRun(TestRunner.java:774)
	at org.testng.TestRunner.run(TestRunner.java:624)
	at org.testng.SuiteRunner.runTest(SuiteRunner.java:359)
	at org.testng.SuiteRunner.runSequentially(SuiteRunner.java:354)
	at org.testng.SuiteRunner.privateRun(SuiteRunner.java:312)
	at org.testng.SuiteRunner.run(SuiteRunner.java:261)
	at org.testng.SuiteRunnerWorker.runSuite(SuiteRunnerWorker.java:52)
	at org.testng.SuiteRunnerWorker.run(SuiteRunnerWorker.java:86)
	at org.testng.TestNG.runSuitesSequentially(TestNG.java:1215)
	at org.testng.TestNG.runSuitesLocally(TestNG.java:1140)
	at org.testng.TestNG.run(TestNG.java:1048)
	at org.testng.remote.AbstractRemoteTestNG.run(AbstractRemoteTestNG.java:132)
	at org.testng.remote.RemoteTestNG.initAndRun(RemoteTestNG.java:230)
	at org.testng.remote.RemoteTestNG.main(RemoteTestNG.java:76)
]]>
    </failure>
  </testcase> <!-- tc03 -->
</testsuite> <!-- com.Selenium.TestNGPackage.TestNGPriority -->
